Scheduler started
Looking for jobs to run
No jobs; waiting until a job is added
【request before】
139735133574912
Exception on /api/task/async_result [GET]
Traceback (most recent call last):
  File "/usr/local/lib/python3.8/site-packages/flask/app.py", line 1523, in full_dispatch_request
    rv = self.dispatch_request()
  File "/usr/local/lib/python3.8/site-packages/flask/app.py", line 1509, in dispatch_request
    return self.ensure_sync(self.view_functions[rule.endpoint])(**req.view_args)
  File "/usr/local/lib/python3.8/site-packages/flask_login/utils.py", line 277, in decorated_view
    return current_app.ensure_sync(func)(*args, **kwargs)
  File "/home/web/app/web/task.py", line 411, in get_result
    return success_response(str(redis_client.get(id), 'utf-8'))
TypeError: decoding to str: need a bytes-like object, NoneType found

During handling of the above exception, another exception occurred:

Traceback (most recent call last):
  File "/usr/local/lib/python3.8/site-packages/flask/app.py", line 2077, in wsgi_app
    response = self.full_dispatch_request()
  File "/usr/local/lib/python3.8/site-packages/flask/app.py", line 1525, in full_dispatch_request
    rv = self.handle_user_exception(e)
  File "/usr/local/lib/python3.8/site-packages/flask_cors/extension.py", line 165, in wrapped_function
    return cors_after_request(app.make_response(f(*args, **kwargs)))
  File "/usr/local/lib/python3.8/site-packages/flask/app.py", line 1391, in handle_user_exception
    return self.ensure_sync(handler)(e)
  File "/home/web/app/web/errors.py", line 16, in framework_error
    return make_error_res(501, e.get_description())
AttributeError: 'TypeError' object has no attribute 'get_description'
【request after】
